<?xml version="1.0" encoding="utf-8"?>
<!-- This URDF was automatically created by SolidWorks to URDF Exporter! Originally created by Stephen Brawner (brawner@gmail.com) 
     Commit Version: 1.6.0-1-g15f4949  Build Version: 1.6.7594.29634
     For more information, please see http://wiki.ros.org/sw_urdf_exporter -->
<robot
  name="harvest-studio">
  <link
    name="harest-base">
    <inertial>
      <origin
        xyz="0.000696907579288617 0.241579417748028 0.0643234810436763"
        rpy="0 0 0" />
      <mass
        value="10.2530883442845" />
      <inertia
        ixx="0.301757152337457"
        ixy="1.10550578941882E-09"
        ixz="1.09640049684721E-07"
        iyy="0.326245406728091"
        iyz="-1.56034601120319E-10"
        izz="0.10209204718156" />
    </inertial>
    <visual>
      <origin
        xyz="0 0 0"
        rpy="0 0 0" />
      <geometry>
        <mesh
          filename="package://harvest-studio/meshes/harest-base.STL" />
      </geometry>
      <material
        name="">
        <color
          rgba="0.752941176470588 0.752941176470588 0.752941176470588 1" />
      </material>
    </visual>
    <collision>
      <origin
        xyz="0 0 0"
        rpy="0 0 0" />
      <geometry>
        <mesh
          filename="package://harvest-studio/meshes/harest-base.STL" />
      </geometry>
    </collision>
  </link>
  <link
    name="camera-link">
    <inertial>
      <origin
        xyz="-0.555798227654505 -1.15796914650996 -0.0127179000558243"
        rpy="0 0 0" />
      <mass
        value="2.78889236681532" />
      <inertia
        ixx="0.00412183232658974"
        ixy="4.07170566456366E-07"
        ixz="5.18842380195653E-08"
        iyy="0.00248184816185608"
        iyz="-0.000513612716556471"
        izz="0.0060380765712014" />
    </inertial>
    <visual>
      <origin
        xyz="0 0 0"
        rpy="0 0 0" />
      <geometry>
        <mesh
          filename="package://harvest-studio/meshes/camera-link.STL" />
      </geometry>
      <material
        name="">
        <color
          rgba="0.792156862745098 0.819607843137255 0.933333333333333 1" />
      </material>
    </visual>
    <collision>
      <origin
        xyz="0 0 0"
        rpy="0 0 0" />
      <geometry>
        <mesh
          filename="package://harvest-studio/meshes/camera-link.STL" />
      </geometry>
    </collision>
  </link>
  <joint
    name="camera_joint"
    type="revolute">
    <origin
      xyz="-0.55495 -0.675 0.80244"
      rpy="-0.20407 0 3.1416" />
    <parent
      link="harest-base" />
    <child
      link="camera-link" />
    <axis
      xyz="1 0 0" />
    <limit
      lower="-0.5"
      upper="0.5"
      effort="0"
      velocity="0" />
  </joint>
</robot>