<?xml version="1.0" encoding="utf-8"?>
<!-- This URDF was automatically created by SolidWorks to URDF Exporter! Originally created by Stephen Brawner (brawner@gmail.com) 
     Commit Version: 1.6.0-1-g15f4949  Build Version: 1.6.7594.29634
     For more information, please see http://wiki.ros.org/sw_urdf_exporter -->
<robot
  name="harvest-studio">
  <link
    name="harest-base">
    <inertial>
      <origin
        xyz="0.00069822 0.24144 0.063798"
        rpy="0 0 0" />
      <mass
        value="10.247" />
      <inertia
        ixx="0.30176"
        ixy="2.765E-10"
        ixz="1.0954E-07"
        iyy="0.32624"
        iyz="7.4555E-11"
        izz="0.10209" />
    </inertial>
    <visual>
      <origin
        xyz="0 0 0"
        rpy="0 0 0" />
      <geometry>
        <mesh
          filename="package://harvest-studio/meshes/harest-base.STL" />
      </geometry>
      <material
        name="">
        <color
          rgba="0.79216 0.81961 0.93333 1" />
      </material>
    </visual>
    <collision>
      <origin
        xyz="0 0 0"
        rpy="0 0 0" />
      <geometry>
        <mesh
          filename="package://harvest-studio/meshes/harest-base.STL" />
      </geometry>
    </collision>
  </link>
  <link
    name="camera-link">
    <inertial>
      <origin
        xyz="-0.5558 -1.158 -0.012718"
        rpy="0 0 0" />
      <mass
        value="2.7889" />
      <inertia
        ixx="0.0041218"
        ixy="4.0717E-07"
        ixz="5.1884E-08"
        iyy="0.0024818"
        iyz="-0.00051361"
        izz="0.0060381" />
    </inertial>
    <visual>
      <origin
        xyz="0 0 0"
        rpy="0 0 0" />
      <geometry>
        <mesh
          filename="package://harvest-studio/meshes/camera-link.STL" />
      </geometry>
      <material
        name="">
        <color
          rgba="0.79216 0.81961 0.93333 1" />
      </material>
    </visual>
    <collision>
      <origin
        xyz="0 0 0"
        rpy="0 0 0" />
      <geometry>
        <mesh
          filename="package://harvest-studio/meshes/camera-link.STL" />
      </geometry>
    </collision>
  </link>
  <joint
    name="camera_joint"
    type="revolute">
    <origin
      xyz="-0.55495 -0.675 0.80244"
      rpy="-0.20407 0 3.1416" />
    <parent
      link="harest-base" />
    <child
      link="camera-link" />
    <axis
      xyz="1 0 0" />
    <limit
      lower="-0.5"
      upper="0.5"
      effort="0"
      velocity="0" />
  </joint>
</robot>